Traceback (most recent call last):
  File "./MAIN.py", line 2, in <module>
    import pycuda.autoinit
ImportError: No module named pycuda.autoinit
Traceback (most recent call last):
  File "./MAIN.py", line 2, in <module>
    import pycuda.autoinit
ImportError: No module named pycuda.autoinit
Traceback (most recent call last):
  File "./MAIN.py", line 2, in <module>
    import pycuda.autoinit
ImportError: No module named pycuda.autoinit
Traceback (most recent call last):
  File "./MAIN.py", line 2, in <module>
    import pycuda.autoinit
ImportError: No module named pycuda.autoinit
Traceback (most recent call last):
  File "./MAIN.py", line 2, in <module>
    import pycuda.autoinit
ImportError: No module named pycuda.autoinit
Traceback (most recent call last):
  File "./MAIN.py", line 2, in <module>
    import pycuda.autoinit
ImportError: No module named pycuda.autoinit
Traceback (most recent call last):
  File "./MAIN.py", line 2, in <module>
    import pycuda.autoinit
ImportError: No module named pycuda.autoinit
Traceback (most recent call last):
  File "./MAIN.py", line 2, in <module>
    import pycuda.autoinit
ImportError: No module named pycuda.autoinit
Traceback (most recent call last):
  File "./MAIN.py", line 2, in <module>
    import pycuda.autoinit
ImportError: No module named pycuda.autoinit
Traceback (most recent call last):
  File "./MAIN.py", line 98, in <module>
    main();
  File "./MAIN.py", line 81, in main
    UVBundle = RSFKM(DataValues, NumClusters, RegParam, ThresholdValue, OutputDirectory)
  File "/cse/home/cscully/Machine_Learning/RSFKM/RSFKM.py", line 256, in RSFKM
    UpdateMembershipMatrix(DataMatrix, MatrixH, S, Centroids, MembershipMatrix, RegParam)
  File "/cse/home/cscully/Machine_Learning/RSFKM/RSFKM.py", line 141, in UpdateMembershipMatrix
    prob.solve(solver=ECOS)
  File "/cse/home/cscully/PyEnv/local/lib/python2.7/site-packages/cvxpy/problems/problem.py", line 209, in solve
    return self._solve(*args, **kwargs)
  File "/cse/home/cscully/PyEnv/local/lib/python2.7/site-packages/cvxpy/problems/problem.py", line 335, in _solve
    self._update_problem_state(results_dict, sym_data, solver)
  File "/cse/home/cscully/PyEnv/local/lib/python2.7/site-packages/cvxpy/problems/problem.py", line 447, in _update_problem_state
    "Solver '%s' failed. Try another solver." % solver.name())
cvxpy.error.SolverError: Solver 'ECOS' failed. Try another solver.
./queue.sh: line 19: syntax error near unexpected token `fi'
./queue.sh: line 19: ` fi'
